Workbook

Sheet PREGÕES CONSOLIDADOS
A1: PREGÃO | B1: ITEM | C1: VEÍCULO | D1: NOMENCLATURA | E1: QTD TR | F1: QTD EMPENHADO | G1: QNT DISPONÍVEL | H1: VALOR UNITÁRIO | I1: VALOR TOTAL | J1: OM TERMO DE REFERÊNCIA | K1: MARCA/MODELO | L1: CNPJ | M1: EMPRESA | N1: CONTATO | O1: E-MAIL | P1: ATA | Q1: VIGÊNCIA | R1: OBSERVAÇÃO
A2: 233_2023 | B2: 1 | C2: E-1 | D2: AMBULÂNCIA DE SUPORTE BÁSICO DE VIDA | E2: 17 | F2: ='233_2023'!E3 -> 13 | G2: ='233_2023'!F3 -> 4 | H2: 334800 | I2: 5691600 | K2: RENAULT - MASTER L3H2 | L2: 38.120.508/0001-04 | M2: G10 TRANSFORMADORA, COMERCIO E SERVICOS LTDA | O2: g10transformadora@gmail.com | P2: 1316/2023 | Q2: 45680
A3: 233_2023 | B3: 2 | C3: E-2 | D3: AMBULÂNCIA DE SUPORTE AVANÇADO DE VIDA | E3: 13 | F3: ='233_2023'!E4 -> 2 | G3: ='233_2023'!F4 -> 11 | H3: 529000 | I3: 6877000 | K3: RENAULT - MASTER L3H2 | L3: 51.552.005/0001-68 | M3: NOVO HORIZONTE COMERCIO E SERVICOS LTDA | P3: 1311/2023 | Q3: 45680 | R3: QTD DISPONÍVEL ERRADA SILOMS
A4: 247_2023 | B4: 1 | C4: C-1/01A/DTS | D4: CAMINHÃO LEVE | E4: 1 | F4: ='247_2023'!E3 -> 1 | G4: ='247_2023'!F3 -> 0 | H4: 305000 | I4: 305000 | J4: CINDACTA 1 | K4: HYUNDAI/ HD80 COM CARROCERIA | L4: 34.263.393/0001-48 | M4: DELTA COMERCIAL E SERVICOS LTDA | N4: 62 98538-1830 | O4: deltacomercial08@gmail.com | P4: 1006 | Q4: 45696
A5: 247_2023 | B5: 1 | C5: C-1/01A/DTS | D5: CAMINHÃO LEVE | E5: 1 | F5: ='247_2023'!E4 -> 1 | G5: ='247_2023'!F4 -> 0 | H5: 305000 | I5: 305000 | J5: CRCEA-SE | K5: HYUNDAI/ HD80 COM CARROCERIA | L5: 34.263.393/0001-48 | M5: DELTA COMERCIAL E SERVICOS LTDA | N5: 62 98538-1830 | O5: deltacomercial08@gmail.com | P5: 1006 | Q5: 45696
A6: 247_2023 | B6: 2 | C6: C-4/01A/DTS | D6: FURGÃO LEVE | E6: 1 | F6: ='247_2023'!E5 -> 1 | G6: ='247_2023'!F5 -> 0 | H6: 144000 | I6: 144000 | J6: DECEA | K6: PEUGEOT PARTNER | L6: 51.552.005/0001-68 | M6: NOVO HORIZONTE COMERCIO E SERVIÇOS LTDA | N6: (62) 32286752 | O6: admnovohorizontecomercio@gmail.com nhcomercio.vendas02@gmail.com | P6: 1326 | Q6: 45654
A7: 247_2023 | B7: 2 | C7: C-4/01A/DTS | D7: FURGÃO LEVE | E7: 1 | F7: ='247_2023'!E6 -> 1 | G7: ='247_2023'!F6 -> 0 | H7: 144000 | I7: 144000 | J7: BACG | K7: PEUGEOT PARTNER | L7: 51.552.005/0001-68 | M7: NOVO HORIZONTE COMERCIO E SERVIÇOS LTDA | N7: (62) 32286752 | O7: admnovohorizontecomercio@gmail.com nhcomercio.vendas02@gmail.com | P7: 1326 | Q7: 45654
A8: 247_2023 | B8: 2 | C8: C-4/01A/DTS | D8: FURGÃO LEVE | E8: 1 | F8: ='247_2023'!E7 -> 1 | G8: ='247_2023'!F7 -> 0 | H8: 144000 | I8: 144000 | J8: BAPV | K8: PEUGEOT PARTNER | L8: 51.552.005/0001-68 | M8: NOVO HORIZONTE COMERCIO E SERVIÇOS LTDA | N8: (62) 32286752 | O8: admnovohorizontecomercio@gmail.com nhcomercio.vendas02@gmail.com | P8: 1326 | Q8: 45654
A9: 247_2023 | B9: 2 | C9: C-4/01A/DTS | D9: FURGÃO LEVE | E9: 3 | F9: ='247_2023'!E8 -> 2 | G9: ='247_2023'!F8 -> 1 | H9: 144000 | I9: 432000 | J9: CINDACTA 3 | K9: PEUGEOT PARTNER | L9: 51.552.005/0001-68 | M9: NOVO HORIZONTE COMERCIO E SERVIÇOS LTDA | N9: (62) 32286752 | O9: admnovohorizontecomercio@gmail.com nhcomercio.vendas02@gmail.com | P9: 1326 | Q9: 45654
A10: 247_2023 | B10: 3 | C10: C-4/02A/DTS | D10: FURGÃO LEVE (TIPO VAN) | E10: 1 | F10: ='247_2023'!E9 -> 1 | G10: ='247_2023'!F9 -> 0 | H10: 253684 | I10: 253684 | J10: CINDACTA 2 | K10: FIAT/ NOVA DUCATO CARGO 2.2 DIESEL 2024 | L10: 16.701.716/0001-56 | M10: FCA FIAT CHRYSLER AUTOMOVEIS BRASIL LTDA | N10: 11 993795516 | O10: graziela.souza@stellantis.com // rodrigo.magalhaes@stellantis.com | P10: 1323 | Q10: 45654
A11: 247_2023 | B11: 3 | C11: C-4/02A/DTS | D11: FURGÃO LEVE (TIPO VAN) | E11: 1 | F11: ='247_2023'!E10 -> 1 | G11: ='247_2023'!F10 -> 0 | H11: 253684 | I11: 253684 | J11: CISCEA | K11: FIAT/ NOVA DUCATO CARGO 2.2 DIESEL 2024 | L11: 16.701.716/0001-56 | M11: FCA FIAT CHRYSLER AUTOMOVEIS BRASIL LTDA | N11: 11 993795516 | O11: graziela.souza@stellantis.com // rodrigo.magalhaes@stellantis.com | P11: 1323 | Q11: 45654
A12: 247_2023 | B12: 3 | C12: C-4/02A/DTS | D12: FURGÃO LEVE (TIPO VAN) | E12: 1 | F12: ='247_2023'!E11 -> 1 | G12: ='247_2023'!F11 -> 0 | H12: 253684 | I12: 253684 | J12: CRCEA-SE | K12: FIAT/ NOVA DUCATO CARGO 2.2 DIESEL 2024 | L12: 16.701.716/0001-56 | M12: FCA FIAT CHRYSLER AUTOMOVEIS BRASIL LTDA | N12: 11 993795516 | O12: graziela.souza@stellantis.com // rodrigo.magalhaes@stellantis.com | P12: 1323 | Q12: 45654
A13: 247_2023 | B13: 3 | C13: C-4/02A/DTS | D13: FURGÃO LEVE (TIPO VAN) | E13: 1 | F13: ='247_2023'!E12 -> 1 | G13: ='247_2023'!F12 -> 0 | H13: 253684 | I13: 253684 | J13: GABAER | K13: FIAT/ NOVA DUCATO CARGO 2.2 DIESEL 2024 | L13: 16.701.716/0001-56 | M13: FCA FIAT CHRYSLER AUTOMOVEIS BRASIL LTDA | N13: 11 993795516 | O13: graziela.souza@stellantis.com // rodrigo.magalhaes@stellantis.com | P13: 1323 | Q13: 45654
A14: 247_2023 | B14: 4 | C14: C-5/02A/DTS | D14: CAMINHÃO BAÚ | E14: 1 | F14: ='247_2023'!E13 -> 1 | G14: ='247_2023'!F13 -> 0 | H14: 518980 | I14: 518980 | J14: CINDACTA 4 | K14: IVECO/ TECTOR 150E21 (4x2) | L14: 46.135.499/0001-45 | M14: FORZA DISTRIBUIDORA LTDA | N14: (62) 9 9967-4771 | O14: temporarioforza@gmail.com | P14: 1007 | Q14: 45716
A15: 247_2023 | B15: 4 | C15: C-5/02A/DTS | D15: CAMINHÃO BAÚ | E15: 1 | F15: ='247_2023'!E14 -> 1 | G15: ='247_2023'!F14 -> 0 | H15: 518980 | I15: 518980 | J15: CISCEA | K15: IVECO/ TECTOR 150E21 (4x2) | L15: 46.135.499/0001-45 | M15: FORZA DISTRIBUIDORA LTDA | N15: (62) 9 9967-4771 | O15: temporarioforza@gmail.com | P15: 1007 | Q15: 45716
... A19: 247_2023 | B19: 5 | C19: C-6/01A/DTS | D19: PICK UP CABINE SIMPLES | E19: 1 | F19: ='247_2023'!E18 -> 1 | G19: ='247_2023'!F18 -> 0 | H19: 103229 | I19: 103229 | J19: GAP-RF | K19: NOVA STRADA FREEDOM CP MT | L19: 16.701.716/0001-56 | M19: FCA FIAT CHRYSLER AUTOMOVEIS BRASIL LTDA | N19: 11 993795516 | O19: graziela.souza@stellantis.com // rodrigo.magalhaes@stellantis.com | P19: 1323 | Q19: 45654
A20: 247_2023 | B20: 6 | C20: C-7/01A/DTS | D20: CAMINHÃO TRUCADO | E20: ='247_2023'!E19 -> 1 | F20: ='247_2023'!E19 -> 1 | G20: ='247_2023'!F19 -> 0 | H20: 595000 | I20: 595000 | J20: PAMERJ | K20: VOLKSWAGEN MODELO 26.260 CONSTELLATION | L20: 11.726.521/0020-00 | M20: TRANSRIO CAMINHOES, ONIBUS, MAQUINAS E MOTORES LTDA | N20: 12 974072062 ou 12 988939333 | O20: marcus.turner@hotmail.com////Edson.aguiar@transrio.com.br | P20: 1325 | Q20: 45696
A21: 247_2023 | B21: 7 | C21: C-9/01A/DTS | D21: REBOQUE CARGA | E21: 4 | F21: ='247_2023'!E20 -> 4 | G21: ='247_2023'!F20 -> 0 | H21: 13682 | I21: 54728 | J21: CINDACTA 3 | K21: CARRETAS RUSSO/ R - RUSSO 1700 1E | L21: 35.157.698/0001-38 | M21: MWD NEGOCIOS & SOLUCOES EIRELI | N21: (22) 998644296 | O21: mwdlicitacao@gmail.com | P21: 1005 | Q21: 45696
A22: 247_2023 | B22: 8 | C22: E-4/02A/DTS | D22: CAMINHÃO-PIPA | E22: 4 | F22: ='247_2023'!E21 -> 3 | G22: ='247_2023'!F21 -> 1 | H22: 790000 | I22: 3160000 | J22: CINDACTA 1 | K22: VOLKSWAGEN TRUCK & BUS IND VEIC AUTOMOTORES | L22: 11.726.521/0020-00 | M22: TRANSRIO CAMINHOES, ONIBUS, MAQUINAS E MOTORES LTDA | N22: 12 974072062 ou 12 988939333 | O22: marcus.turner@hotmail.com////Edson.aguiar@transrio.com.br | P22: 1325 | Q22: 45696
A23: 247_2023 | B23: 9 | C23: E-8/01A/DTS | D23: CARRO GUINCHO SOCORRO LEVE | E23: 1 | F23: ='247_2023'!E22 -> 1 | G23: ='247_2023'!F22 -> 0 | H23: 649900 | I23: 649900 | J23: CINDACTA 2 | K23: VOLKSWAGEN / 14210 PLATAFORMA AUTO SOCORRO | L23: 11.726.521/0020-00 | M23: TRANSRIO CAMINHOES, ONIBUS, MAQUINAS E MOTORES LTDA | N23: 12 974072062 ou 12 988939333 | O23: marcus.turner@hotmail.com////Edson.aguiar@transrio.com.br | P23: 1325 | Q23: 45696
A24: 247_2023 | B24: 9 | C24: E-8/01A/DTS | D24: CARRO GUINCHO SOCORRO LEVE | E24: 1 | F24: ='247_2023'!E23 -> 0 | G24: ='247_2023'!F23 -> 1 | H24: 649900 | I24: 649900 | J24: GAP-SP | K24: VOLKSWAGEN / 14210 PLATAFORMA AUTO SOCORRO | L24: 11.726.521/0020-00 | M24: TRANSRIO CAMINHOES, ONIBUS, MAQUINAS E MOTORES LTDA | N24: 12 974072062 ou 12 988939333 | O24: marcus.turner@hotmail.com////Edson.aguiar@transrio.com.br | P24: 1325 | Q24: 45696
A25: 247_2023 | B25: 10 | C25: E-10/02A/DTS | D25: EMPILHADEIRA | E25: 1 | F25: ='247_2023'!E24 -> x | G25: ='247_2023'!F24 -> x | H25: REVOGADO | I25: R$ - | K25: x | L25: x | M25: x | P25: x | Q25: x | R25: x
A26: 247_2023 | B26: 10 | C26: E-10/02A/DTS | D26: EMPILHADEIRA | E26: 1 | F26: ='247_2023'!E25 -> x | G26: ='247_2023'!F25 -> x | H26: REVOGADO | I26: R$ - | J26: CINDACTA 2 | K26: x | L26: x | M26: x | P26: x | Q26: x | R26: x
A27: 247_2023 | B27: 10 | C27: E-10/02A/DTS | D27: EMPILHADEIRA | E27: 4 | F27: ='247_2023'!E26 -> x | G27: ='247_2023'!F26 -> x | H27: REVOGADO | I27: R$ - | J27: CINDACTA 3 | K27: x | L27: x | M27: x | P27: x | Q27: x | R27: x
A28: 247_2023 | B28: 10 | C28: E-10/02A/DTS | D28: EMPILHADEIRA | E28: 1 | F28: ='247_2023'!E27 -> x | G28: ='247_2023'!F27 -> x | H28: REVOGADO | I28: R$ - | J28: CINDACTA 4 | K28: x | L28: x | M28: x | P28: x | Q28: x | R28: x
A29: 247_2023 | B29: 10 | C29: E-10/02A/DTS | D29: EMPILHADEIRA | E29: 1 | F29: ='247_2023'!E28 -> x | G29: ='247_2023'!F28 -> x | H29: REVOGADO | I29: R$ - | J29: CRCEA-SE | K29: x | L29: x | M29: x | P29: x | Q29: x | R29: x
A30: 247_2023 | B30: 11 | C30: E-12/03B/DTS | D30: TRATOR DE RODAS COM ROÇADEIRA | E30: 1 | F30: ='247_2023'!E29 -> x | G30: ='247_2023'!F29 -> x | I30: R$ - | J30: ERA PRA ONDE? | K30: x | L30: x | M30: x | P30: x | Q30: x | R30: x
A31: 247_2023 | B31: 11 | C31: E-12/03B/DTS | D31: TRATOR DE RODAS COM ROÇADEIRA | E31: 4 | F31: ='247_2023'!E30 -> x | G31: ='247_2023'!F30 -> x | I31: R$ - | J31: CINDACTA 3 | K31: x | L31: x | M31: x | P31: x | Q31: x | R31: x
A32: 247_2023 | B32: 11 | C32: E-12/03B/DTS | D32: TRATOR DE RODAS COM ROÇADEIRA | E32: 1 | F32: ='247_2023'!E31 -> x | G32: ='247_2023'!F31 -> x | I32: R$ - | J32: GAP-MN | K32: x | L32: x | M32: x | P32: x | Q32: x | R32: x
A33: 247_2023 | B33: 12 | C33: E-13/01A/DTS | D33: TRATOR DE ESTEIRAS | E33: 1 | F33: ='247_2023'!E32 -> 0 | G33: ='247_2023'!F32 -> 1 | H33: 1189999.8 | I33: 1189999.8 | J33: CPBV | K33: UNFORKLIFT/ UN16YE
A34: 247_2023 | B34: 13 | C34: E-14/01A/DTS | D34: MICROTRATOR COM APARADOR DE GRAMA | E34: 13 | F34: ='247_2023'!E33 -> x | G34: ='247_2023'!F33 -> x | I34: R$ - | J34: ERA PRA ONDE? | K34: x | L34: x | M34: x | P34: x | Q34: x | R34: x
A35: 247_2023 | B35: 14 | C35: E-15/01A/DTS | D35: CAMINHÃO EQUIPADO COM GUINDASTE HIDRÁULICO | E35: 1 | F35: ='247_2023'!E34 -> 1 | G35: ='247_2023'!F34 -> 0 | H35: 979980 | I35: 979980 | J35: CINDACTA 1 | K35: VOLVO/ VMX 290 (6x4) | L35: 46.135.499/0001-45 | M35: FORZA DISTRIBUIDORA LTDA | N35: (62) 9 9967-4771 | O35: temporarioforza@gmail.com | P35: 1007 | Q35: 45716
A36: 247_2023 | B36: 14 | C36: E-15/01A/DTS | D36: CAMINHÃO EQUIPADO COM GUINDASTE HIDRÁULICO | E36: 1 | F36: ='247_2023'!E35 -> 1 | G36: ='247_2023'!F35 -> 0 | H36: 979980 | I36: 979980 | J36: CINDACTA 2 | K36: VOLVO/ VMX 290 (6x4) | L36: 46.135.499/0001-45 | M36: FORZA DISTRIBUIDORA LTDA | N36: (62) 9 9967-4771 | O36: temporarioforza@gmail.com | P36: 1007 | Q36: 45716
A37: 247_2023 | B37: 14 | C37: E-15/01A/DTS | D37: CAMINHÃO EQUIPADO COM GUINDASTE HIDRÁULICO | E37: 1 | F37: ='247_2023'!E36 -> 1 | G37: ='247_2023'!F36 -> 0 | H37: 979980 | I37: 979980 | J37: CINDACTA 3 | K37: VOLVO/ VMX 290 (6x4) | L37: 46.135.499/0001-45 | M37: FORZA DISTRIBUIDORA LTDA | N37: (62) 9 9967-4771 | O37: temporarioforza@gmail.com | P37: 1007 | Q37: 45716
A38: 247_2023 | B38: 14 | C38: E-15/01A/DTS | D38: CAMINHÃO EQUIPADO COM GUINDASTE HIDRÁULICO | E38: 1 | F38: ='247_2023'!E37 -> 1 | G38: ='247_2023'!F37 -> 0 | H38: 979980 | I38: 979980 | J38: GAP-AF | K38: VOLVO/ VMX 290 (6x4) | L38: 46.135.499/0001-45 | M38: FORZA DISTRIBUIDORA LTDA | N38: (62) 9 9967-4771 | O38: temporarioforza@gmail.com | P38: 1007 | Q38: 45716
A39: 247_2023 | B39: 14 | C39: E-15/01A/DTS | D39: CAMINHÃO EQUIPADO COM GUINDASTE HIDRÁULICO | E39: 1 | F39: ='247_2023'!E38 -> 1 | G39: ='247_2023'!F38 -> 0 | H39: 979980 | I39: 979980 | J39: GAP-SJ | K39: VOLVO/ VMX 290 (6x4) | L39: 46.135.499/0001-45 | M39: FORZA DISTRIBUIDORA LTDA | N39: (62) 9 9967-4771 | O39: temporarioforza@gmail.com | P39: 1007 | Q39: 45716
A40: 247_2023 | B40: 15 | C40: E-16/01A/DTS | D40: CAMINHÃO EQUIPADO COM ELEVADOR HIDRÁULICO E CESTO AÉREO | E40: 1 | F40: ='247_2023'!E39 -> 1 | G40: ='247_2023'!F39 -> 0 | H40: 592400 | I40: 592400 | J40: GAP-SJ | K40: VOLKSWAGEN/9180 COM ELEVADOR HIDRAULICO E CESTO AEREO | L40: 11.726.521/0020-00 | M40: TRANSRIO CAMINHOES, ONIBUS, MAQUINAS E MOTORES LTDA | N40: 12 974072062 ou 12 988939333 | O40: marcus.turner@hotmail.com////Edson.aguiar@transrio.com.br | P40: 1325 | Q40: 45696
A41: 247_2023 | B41: 16 | C41: E-17/01A/DTS | D41: RETROESCAVADEIRA COM PÁ CARREGADEIRA | E41: 1 | F41: ='247_2023'!E40 -> X | G41: ='247_2023'!F40 -> X | H41: 474000 | I41: 474000 | J41: AFA | R41: AGUARDANDO RECURSO
A42: 247_2023 | B42: 16 | C42: E-17/01A/DTS | D42: RETROESCAVADEIRA COM PÁ CARREGADEIRA | E42: 1 | F42: ='247_2023'!E41 -> X | G42: ='247_2023'!F41 -> X | H42: 474000 | I42: 474000 | J42: BACG | R42: AGUARDANDO RECURSO
A43: 247_2023 | B43: 16 | C43: E-17/01A/DTS | D43: RETROESCAVADEIRA COM PÁ CARREGADEIRA | E43: 1 | F43: ='247_2023'!E42 -> X | G43: ='247_2023'!F42 -> X | H43: 474000 | I43: 474000 | J43: BAFL | R43: AGUARDANDO RECURSO
...

Sheet Tabela dinâmica 1

Sheet 90057_2026
A1: PAG : 67106.002167/2025-64 | I1: STATUS em 07/07/26 | K1: CERTAME SILOMS P260005
A2: ITEM | B2: VEÍCULO | C2: NOMENCLATURA | D2: QTD TR | E2: QTD EMPENHADO | F2: QNT DISPONÍVEL | G2: VALOR UNITÁRIO | H2: VALOR TOTAL | I2: OM RECEBEDORA | J2: MARCA/MODELO | K2: EMPRESA | L2: CNPJ | M2: CONTATO | N2: EMAIL | O2: ATA | P2: VIGÊNCIA | Q2: OBS
A3: 1 | B3: P1-01A-DTS | C3: VEÍCULO ESPECIAL | D3: 1 | E3: 0 | F3: =D3-E3 -> 1 | G3: 216500 | H3: =G3*D3 -> 216500 | I3: AFA | J3: TOYOTA COROLLA XEI 2.0 FLEX AT (2062/2026) | K3: VCS IMPLEMENTOS E VEICULOS LTDA | L3: 38.428.119/0001-32 | M3: (27) 3191-0855 / (27) 3191-0875 | N3: licitacao@vcsimplementos.com | O3: 755/2026 | P3: 46591
A4: 1 | B4: P1-01A-DTS | C4: VEÍCULO ESPECIAL | D4: 1 | E4: 0 | F4: =D4-E4 -> 1 | G4: 216500 | H4: =G4*D4 -> 216500 | I4: BAFL | J4: TOYOTA COROLLA XEI 2.0 FLEX AT (2062/2026) | K4: VCS IMPLEMENTOS E VEICULOS LTDA | L4: 38.428.119/0001-32 | M4: (27) 3191-0855 / (27) 3191-0875 | N4: licitacao@vcsimplementos.com | O4: 755/2026 | P4: 46591
A5: 1 | B5: P1-01A-DTS | C5: VEÍCULO ESPECIAL | D5: 1 | E5: 0 | F5: =D5-E5 -> 1 | G5: 216500 | H5: =G5*D5 -> 216500 | I5: BAFZ | J5: TOYOTA COROLLA XEI 2.0 FLEX AT (2062/2026) | K5: VCS IMPLEMENTOS E VEICULOS LTDA | L5: 38.428.119/0001-32 | M5: (27) 3191-0855 / (27) 3191-0875 | N5: licitacao@vcsimplementos.com | O5: 755/2026 | P5: 46591
A6: 1 | B6: P1-01A-DTS | C6: VEÍCULO ESPECIAL | D6: 1 | E6: 0 | F6: =D6-E6 -> 1 | G6: 216500 | H6: =G6*D6 -> 216500 | I6: BANT | J6: TOYOTA COROLLA XEI 2.0 FLEX AT (2062/2026) | K6: VCS IMPLEMENTOS E VEICULOS LTDA | L6: 38.428.119/0001-32 | M6: (27) 3191-0855 / (27) 3191-0875 | N6: licitacao@vcsimplementos.com | O6: 755/2026 | P6: 46591
A7: 1 | B7: P1-01A-DTS | C7: VEÍCULO ESPECIAL | D7: 1 | E7: 0 | F7: =D7-E7 -> 1 | G7: 216500 | H7: =G7*D7 -> 216500 | I7: BASM | J7: TOYOTA COROLLA XEI 2.0 FLEX AT (2062/2026) | K7: VCS IMPLEMENTOS E VEICULOS LTDA | L7: 38.428.119/0001-32 | M7: (27) 3191-0855 / (27) 3191-0875 | N7: licitacao@vcsimplementos.com | O7: 755/2026 | P7: 46591
A8: 1 | B8: P1-01A-DTS | C8: VEÍCULO ESPECIAL | D8: 1 | E8: 0 | F8: =D8-E8 -> 1 | G8: 216500 | H8: =G8*D8 -> 216500 | I8: BASV | J8: TOYOTA COROLLA XEI 2.0 FLEX AT (2062/2026) | K8: VCS IMPLEMENTOS E VEICULOS LTDA | L8: 38.428.119/0001-32 | M8: (27) 3191-0855 / (27) 3191-0875 | N8: licitacao@vcsimplementos.com | O8: 755/2026 | P8: 46591
A9: 1 | B9: P1-01A-DTS | C9: VEÍCULO ESPECIAL | D9: 1 | E9: 0 | F9: =D9-E9 -> 1 | G9: 216500 | H9: =G9*D9 -> 216500 | I9: EEAR | J9: TOYOTA COROLLA XEI 2.0 FLEX AT (2062/2026) | K9: VCS IMPLEMENTOS E VEICULOS LTDA | L9: 38.428.119/0001-32 | M9: (27) 3191-0855 / (27) 3191-0875 | N9: licitacao@vcsimplementos.com | O9: 755/2026 | P9: 46591
A10: 1 | B10: P1-01A-DTS | C10: VEÍCULO ESPECIAL | D10: 1 | E10: 0 | F10: =D10-E10 -> 1 | G10: 216500 | H10: =G10*D10 -> 216500 | I10: EPCAR | J10: TOYOTA COROLLA XEI 2.0 FLEX AT (2062/2026) | K10: VCS IMPLEMENTOS E VEICULOS LTDA | L10: 38.428.119/0001-32 | M10: (27) 3191-0855 / (27) 3191-0875 | N10: licitacao@vcsimplementos.com | O10: 755/2026 | P10: 46591
A11: 1 | B11: P1-01A-DTS | C11: VEÍCULO ESPECIAL | D11: 1 | E11: 0 | F11: =D11-E11 -> 1 | G11: 216500 | H11: =G11*D11 -> 216500 | I11: GAP-AF | J11: TOYOTA COROLLA XEI 2.0 FLEX AT (2062/2026) | K11: VCS IMPLEMENTOS E VEICULOS LTDA | L11: 38.428.119/0001-32 | M11: (27) 3191-0855 / (27) 3191-0875 | N11: licitacao@vcsimplementos.com | O11: 755/2026 | P11: 46591
A12: 1 | B12: P1-01A-DTS | C12: VEÍCULO ESPECIAL | D12: 1 | E12: 0 | F12: =D12-E12 -> 1 | G12: 216500 | H12: =G12*D12 -> 216500 | I12: GAP-BE | J12: TOYOTA COROLLA XEI 2.0 FLEX AT (2062/2026) | K12: VCS IMPLEMENTOS E VEICULOS LTDA | L12: 38.428.119/0001-32 | M12: (27) 3191-0855 / (27) 3191-0875 | N12: licitacao@vcsimplementos.com | O12: 755/2026 | P12: 46591
A13: 1 | B13: P1-01A-DTS | C13: VEÍCULO ESPECIAL | D13: 10 | E13: 0 | F13: =D13-E13 -> 10 | G13: 216500 | H13: =G13*D13 -> 2165000 | I13: GAP-BR | J13: TOYOTA COROLLA XEI 2.0 FLEX AT (2062/2026) | K13: VCS IMPLEMENTOS E VEICULOS LTDA | L13: 38.428.119/0001-32 | M13: (27) 3191-0855 / (27) 3191-0875 | N13: licitacao@vcsimplementos.com | O13: 755/2026 | P13: 46591
A14: 1 | B14: P1-01A-DTS | C14: VEÍCULO ESPECIAL | D14: 3 | E14: 0 | F14: =D14-E14 -> 3 | G14: 216500 | H14: =G14*D14 -> 649500 | I14: GAP-RJ | J14: TOYOTA COROLLA XEI 2.0 FLEX AT (2062/2026) | K14: VCS IMPLEMENTOS E VEICULOS LTDA | L14: 38.428.119/0001-32 | M14: (27) 3191-0855 / (27) 3191-0875 | N14: licitacao@vcsimplementos.com | O14: 755/2026 | P14: 46591
A15: 1 | B15: P1-01A-DTS | C15: VEÍCULO ESPECIAL | D15: 7 | E15: 0 | F15: =D15-E15 -> 7 | G15: 216500 | H15: =G15*D15 -> 1515500 | I15: GAP-SP | J15: TOYOTA COROLLA XEI 2.0 FLEX AT (2062/2026) | K15: VCS IMPLEMENTOS E VEICULOS LTDA | L15: 38.428.119/0001-32 | M15: (27) 3191-0855 / (27) 3191-0875 | N15: licitacao@vcsimplementos.com | O15: 755/2026 | P15: 46591

Sheet 90146_2025
A1: 120 | C1: STATUS em 29/09/25 | E1: 67106.002167/2025-64
A2: ITEM | B2: VEÍCULO | C2: NOMENCLATURA | D2: QTD TR | E2: QTD EMPENHADO | F2: QNT DISPONÍVEL | H2: VALOR UNITÁRIO | I2: VALOR TOTAL | J2: OM RECEBEDORA | K2: MARCA/MODELO | M2: EMPRESA | N2: CONTATO | O2: EMAIL | P2: ATA | Q2: VIGÊNCIA | R2: OBS
A3: 1 P250003 | B3: C1-01A-DTS | C3: CAMINHÃO LEVE | D3: 1 | E3: 1 | F3: =D3-E3 -> 0 | H3: 343460 | I3: =H3*D3 -> 343460 | J3: AFA | K3: FOTON 916 | L3: 46.135.499/0002-26 | M3: FORZA DISTRIBUIDORA LTDA | Q3: 46351 | R3: item 7.6.1 tr 305
A4: 1 P250003 | B4: C1-01A-DTS | C4: CAMINHÃO LEVE | D4: 1 | E4: 1 | F4: =D4-E4 -> 0 | H4: 343460 | I4: =H4*D4 -> 343460 | J4: BAAN | K4: FOTON 917 | L4: 46.135.499/0002-26 | M4: FORZA DISTRIBUIDORA LTDA | Q4: 46351
A5: 1 P250003 | B5: C1-01A-DTS | C5: CAMINHÃO LEVE | D5: 1 | E5: 1 | F5: =D5-E5 -> 0 | H5: 343460 | I5: =H5*D5 -> 343460 | J5: BACG | K5: FOTON 918 | L5: 46.135.499/0002-26 | M5: FORZA DISTRIBUIDORA LTDA | Q5: 46351
A6: 1 P250003 | B6: C1-01A-DTS | C6: CAMINHÃO LEVE | D6: 1 | E6: 0 | F6: =D6-E6 -> 1 | H6: 343460 | I6: =H6*D6 -> 343460 | J6: BAPV | K6: FOTON 919 | L6: 46.135.499/0002-26 | M6: FORZA DISTRIBUIDORA LTDA | Q6: 46351
A7: 1 P250003 | B7: C1-01A-DTS | C7: CAMINHÃO LEVE | D7: 1 | E7: 1 | F7: =D7-E7 -> 0 | H7: 343460 | I7: =H7*D7 -> 343460 | J7: BASM | K7: FOTON 920 | L7: 46.135.499/0002-26 | M7: FORZA DISTRIBUIDORA LTDA | Q7: 46351
A8: 1 P250003 | B8: C1-01A-DTS | C8: CAMINHÃO LEVE | D8: 1 | E8: 0 | F8: =D8-E8 -> 1 | H8: 343460 | I8: =H8*D8 -> 343460 | J8: COMARA | K8: FOTON 921 | L8: 46.135.499/0002-26 | M8: FORZA DISTRIBUIDORA LTDA | Q8: 46351
A9: 1 P250003 | B9: C1-01A-DTS | C9: CAMINHÃO LEVE | D9: 1 | E9: 0 | F9: =D9-E9 -> 1 | H9: 343460 | I9: =H9*D9 -> 343460 | J9: GAP-AF | K9: FOTON 922 | L9: 46.135.499/0002-26 | M9: FORZA DISTRIBUIDORA LTDA | Q9: 46351
A10: 1 P250003 | B10: C1-01A-DTS | C10: CAMINHÃO LEVE | D10: 1 | E10: 0 | F10: =D10-E10 -> 1 | H10: 343460 | I10: =H10*D10 -> 343460 | J10: GAP-CO | K10: FOTON 923 | L10: 46.135.499/0002-26 | M10: FORZA DISTRIBUIDORA LTDA | Q10: 46351
A11: 1 P250003 | B11: C1-01A-DTS | C11: CAMINHÃO LEVE | D11: 1 | E11: 0 | F11: =D11-E11 -> 1 | H11: 343460 | I11: =H11*D11 -> 343460 | J11: GAP-DF | K11: FOTON 924 | L11: 46.135.499/0002-26 | M11: FORZA DISTRIBUIDORA LTDA | Q11: 46351
A12: 1 P250003 | B12: C1-01A-DTS | C12: CAMINHÃO LEVE | D12: 1 | E12: 0 | F12: =D12-E12 -> 1 | H12: 343460 | I12: =H12*D12 -> 343460 | J12: GAP-GL | K12: FOTON 925 | L12: 46.135.499/0002-26 | M12: FORZA DISTRIBUIDORA LTDA | Q12: 46351
A13: 1 P250003 | B13: C1-01A-DTS | C13: CAMINHÃO LEVE | D13: 1 | E13: 1 | F13: =D13-E13 -> 0 | H13: 343460 | I13: =H13*D13 -> 343460 | J13: GAP-RF | K13: FOTON 926 | L13: 46.135.499/0002-26 | M13: FORZA DISTRIBUIDORA LTDA | Q13: 46351
A14: 1 P250003 | B14: C1-01A-DTS | C14: CAMINHÃO LEVE | D14: 1 | E14: 0 | F14: =D14-E14 -> 1 | H14: 343460 | I14: =H14*D14 -> 343460 | J14: GAP-RJ | K14: FOTON 927 | L14: 46.135.499/0002-26 | M14: FORZA DISTRIBUIDORA LTDA | Q14: 46351
A15: 1 P250003 | B15: C1-01A-DTS | C15: CAMINHÃO LEVE | D15: 1 | E15: 0 | F15: =D15-E15 -> 1 | H15: 343460 | I15: =H15*D15 -> 343460 | J15: GAP-SJ | K15: FOTON 928 | L15: 46.135.499/0002-26 | M15: FORZA DISTRIBUIDORA LTDA | Q15: 46351
... A24: 2 P250003 | B24: C2-01A-DTS | C24: CAMINHÃO MÉDIO/PESADO | D24: 1 | E24: 1 | F24: =D24-E24 -> 0 | H24: 437680 | I24: =H24*D24 -> 437680 | J24: GAP-SJ | K24: FOTON 1722 | L24: 46.135.499/0002-26 | M24: FORZA DISTRIBUIDORA LTDA | Q24: 46351
A25: 3 | B25: C3-01A-DTS | C25: SEMIRREBOQUE | D25: 1 | E25: 0 | F25: =D25-E25 -> 1 | I25: =H25*D25 -> 0 | J25: COMARA
A26: 3 | B26: C3-01A-DTS | C26: SEMIRREBOQUE | D26: 1 | E26: 0 | F26: =D26-E26 -> 1 | I26: =H26*D26 -> 0 | J26: BASM
A27: 3 | B27: C3-01A-DTS | C27: SEMIRREBOQUE | D27: 1 | E27: 0 | F27: =D27-E27 -> 1 | I27: =H27*D27 -> 0 | J27: CPBV-CC
A28: 3 | B28: C3-01A-DTS | C28: SEMIRREBOQUE | D28: 1 | E28: 0 | F28: =D28-E28 -> 1 | I28: =H28*D28 -> 0 | J28: GAP-GL
A29: 3 | B29: C3-01A-DTS | C29: SEMIRREBOQUE | D29: 1 | E29: 0 | F29: =D29-E29 -> 1 | I29: =H29*D29 -> 0 | J29: GAP-RJ
A30: 3 | B30: C3-01A-DTS | C30: SEMIRREBOQUE | D30: 1 | E30: 0 | F30: =D30-E30 -> 1 | I30: =H30*D30 -> 0 | J30: GAP-SP
A31: 4 P250004 | B31: C4-02A-DTS | C31: FURGÃO LEVE | D31: 1 | E31: 1 | F31: =D31-E31 -> 0 | H31: 290000 | I31: =H31*D31 -> 290000 | J31: AFA | K31: MASTER L2H2 FURGÃO 150 CV DIESEL 0KM | L31: 29.987.662/0001-89 | M31: SOCIETE COMERCIO DE VEICULOS LTDA
A32: 4 P250004 | B32: C4-02A-DTS | C32: FURGÃO LEVE | D32: 1 | E32: 1 | F32: =D32-E32 -> 0 | H32: 290000 | I32: =H32*D32 -> 290000 | J32: BAAN | K32: MASTER L2H2 FURGÃO 150 CV DIESEL 0KM | L32: 29.987.662/0001-89 | M32: SOCIETE COMERCIO DE VEICULOS LTDA | Q32: 46347
A33: 4 P250004 | B33: C4-02A-DTS | C33: FURGÃO LEVE | D33: 1 | E33: 1 | F33: =D33-E33 -> 0 | H33: 290000 | I33: =H33*D33 -> 290000 | J33: BANT | K33: MASTER L2H2 FURGÃO 150 CV DIESEL 0KM | L33: 29.987.662/0001-89 | M33: SOCIETE COMERCIO DE VEICULOS LTDA | Q33: 46347
A34: 4 P250004 | B34: C4-02A-DTS | C34: FURGÃO LEVE | D34: 1 | E34: 1 | F34: =D34-E34 -> 0 | H34: 290000 | I34: =H34*D34 -> 290000 | J34: BASM | K34: MASTER L2H2 FURGÃO 150 CV DIESEL 0KM | L34: 29.987.662/0001-89 | M34: SOCIETE COMERCIO DE VEICULOS LTDA | Q34: 46347
A35: 4 P250004 | B35: C4-02A-DTS | C35: FURGÃO LEVE | D35: 1 | E35: 1 | F35: =D35-E35 -> 0 | H35: 290000 | I35: =H35*D35 -> 290000 | J35: COMARA | K35: MASTER L2H2 FURGÃO 150 CV DIESEL 0KM | L35: 29.987.662/0001-89 | M35: SOCIETE COMERCIO DE VEICULOS LTDA | Q35: 46347
A36: 4 P250004 | B36: C4-02A-DTS | C36: FURGÃO LEVE | D36: 1 | E36: 1 | F36: =D36-E36 -> 0 | H36: 290000 | I36: =H36*D36 -> 290000 | J36: DECEA | K36: MASTER L2H2 FURGÃO 150 CV DIESEL 0KM | L36: 29.987.662/0001-89 | M36: SOCIETE COMERCIO DE VEICULOS LTDA | Q36: 46347
A37: 4 P250004 | B37: C4-02A-DTS | C37: FURGÃO LEVE | D37: 1 | E37: 0 | F37: =D37-E37 -> 1 | H37: 290000 | I37: =H37*D37 -> 290000 | J37: EPCAR | K37: MASTER L2H2 FURGÃO 150 CV DIESEL 0KM | L37: 29.987.662/0001-89 | M37: SOCIETE COMERCIO DE VEICULOS LTDA | Q37: 46347
A38: 4 P250004 | B38: C4-02A-DTS | C38: FURGÃO LEVE | D38: 1 | E38: 1 | F38: =D38-E38 -> 0 | H38: 290000 | I38: =H38*D38 -> 290000 | J38: GAP-AF | K38: MASTER L2H2 FURGÃO 150 CV DIESEL 0KM | L38: 29.987.662/0001-89 | M38: SOCIETE COMERCIO DE VEICULOS LTDA | Q38: 46347
A39: 4 P250004 | B39: C4-02A-DTS | C39: FURGÃO LEVE | D39: 1 | E39: 1 | F39: =D39-E39 -> 0 | H39: 290000 | I39: =H39*D39 -> 290000 | J39: GABAER | K39: MASTER L2H2 FURGÃO 150 CV DIESEL 0KM | L39: 29.987.662/0001-89 | M39: SOCIETE COMERCIO DE VEICULOS LTDA | Q39: 46347
A40: 4 P250004 | B40: C4-02A-DTS | C40: FURGÃO LEVE | D40: 1 | E40: 1 | F40: =D40-E40 -> 0 | H40: 290000 | I40: =H40*D40 -> 290000 | J40: GAP-CO | K40: MASTER L2H2 FURGÃO 150 CV DIESEL 0KM | L40: 29.987.662/0001-89 | M40: SOCIETE COMERCIO DE VEICULOS LTDA | Q40: 46347
A41: 4 P250004 | B41: C4-02A-DTS | C41: FURGÃO LEVE | D41: 1 | E41: 0 | F41: =D41-E41 -> 1 | H41: 290000 | I41: =H41*D41 -> 290000 | J41: GAP-DF | K41: MASTER L2H2 FURGÃO 150 CV DIESEL 0KM | L41: 29.987.662/0001-89 | M41: SOCIETE COMERCIO DE VEICULOS LTDA | Q41: 46347
A42: 4 P250004 | B42: C4-02A-DTS | C42: FURGÃO LEVE | D42: 1 | E42: 0 | F42: =D42-E42 -> 1 | H42: 290000 | I42: =H42*D42 -> 290000 | J42: GAP-GL | K42: MASTER L2H2 FURGÃO 150 CV DIESEL 0KM | L42: 29.987.662/0001-89 | M42: SOCIETE COMERCIO DE VEICULOS LTDA | Q42: 46347
A43: 4 P250004 | B43: C4-02A-DTS | C43: FURGÃO LEVE | D43: 1 | E43: 1 | F43: =D43-E43 -> 0 | H43: 290000 | I43: =H43*D43 -> 290000 | J43: GAP-SJ | K43: MASTER L2H2 FURGÃO 150 CV DIESEL 0KM | L43: 29.987.662/0001-89 | M43: SOCIETE COMERCIO DE VEICULOS LTDA | Q43: 46347
... A45: 4 P250004 | B45: C4-02A-DTS | C45: FURGÃO LEVE | D45: 1 | E45: 0 | F45: =D45-E45 -> 1 | H45: 290000 | I45: =H45*D45 -> 290000 | J45: PAME-RJ | K45: MASTER L2H2 FURGÃO 150 CV DIESEL 0KM | L45: 29.987.662/0001-89 | M45: SOCIETE COMERCIO DE VEICULOS LTDA | Q45: 46347
A46: 5 | B46: C5-02A-DTS | C46: CAMINHÃO BAÚ | D46: 1 | E46: 0 | F46: =D46-E46 -> 1 | I46: =H46*D46 -> 0 | J46: AFA
A47: 5 | B47: C5-02A-DTS | C47: CAMINHÃO BAÚ | D47: 1 | E47: 0 | F47: =D47-E47 -> 1 | I47: =H47*D47 -> 0 | J47: BACG
A48: 5 | B48: C5-02A-DTS | C48: CAMINHÃO BAÚ | D48: 1 | E48: 0 | F48: =D48-E48 -> 1 | I48: =H48*D48 -> 0 | J48: BASM
A49: 5 | B49: C5-02A-DTS | C49: CAMINHÃO BAÚ | D49: 1 | E49: 0 | F49: =D49-E49 -> 1 | I49: =H49*D49 -> 0 | J49: CLA
...

Sheet 90127_2025
A1: cae | B1: 67106.000472/2025-11 | C1: STATUS ABERTURA DIA 14/04
A2: ITEM | B2: VEÍCULO | C2: NOMENCLATURA | D2: QTD TR | E2: QTD EMPENHADO | F2: QTD DISPONÍVEL | G2: VALOR UNITÁRIO | H2: VALOR TOTAL | I2: OM RECEBEDORA | J2: MARCA | K2: CNPJ | L2: EMPRESA | M2: CONTATO | N2: EMAIL | O2: ATA | P2: VIGÊNCIA | Q2: OBS
A3: 1 | B3: P12-02A-DTS | C3: Carro de Operações | D3: 1 | E3: 0 | F3: =D3-E3 -> 1 | G3: 287400 | H3: =D3*G3 -> 287400 | I3: GAP-CO | J3: FIAT TITANO | K3: 38.428.119/0001-32 | L3: VCS IMPLEMENTOS E VEICULOS LTDA
A4: 1 | B4: P12-02A-DTS | C4: Carro de Operações | D4: 1 | E4: 0 | F4: =D4-E4 -> 1 | G4: 287400 | H4: =D4*G4 -> 287400 | I4: BASM | J4: FIAT TITANO | K4: 38.428.119/0001-32 | L4: VCS IMPLEMENTOS E VEICULOS LTDA
A5: 1 | B5: P12-02A-DTS | C5: Carro de Operações | D5: 1 | E5: 0 | F5: =D5-E5 -> 1 | G5: 287400 | H5: =D5*G5 -> 287400 | I5: GAP-BE | J5: FIAT TITANO | K5: 38.428.119/0001-32 | L5: VCS IMPLEMENTOS E VEICULOS LTDA
A6: 1 | B6: P12-02A-DTS | C6: Carro de Operações | D6: 1 | E6: 0 | F6: =D6-E6 -> 1 | G6: 287400 | H6: =D6*G6 -> 287400 | I6: BANT | J6: FIAT TITANO | K6: 38.428.119/0001-32 | L6: VCS IMPLEMENTOS E VEICULOS LTDA
A7: 1 | B7: P12-02A-DTS | C7: Carro de Operações | D7: 1 | E7: 0 | F7: =D7-E7 -> 1 | G7: 287400 | H7: =D7*G7 -> 287400 | I7: GAP-SP | J7: FIAT TITANO | K7: 38.428.119/0001-32 | L7: VCS IMPLEMENTOS E VEICULOS LTDA
A8: 1 | B8: P12-02A-DTS | C8: Carro de Operações | D8: 1 | E8: 0 | F8: =D8-E8 -> 1 | G8: 287400 | H8: =D8*G8 -> 287400 | I8: BABV | J8: FIAT TITANO | K8: 38.428.119/0001-32 | L8: VCS IMPLEMENTOS E VEICULOS LTDA

Sheet 90034_2025
A1: cae | B1: 67106.000472/2025-11 | C1: STATUS ABERTURA DIA 14/04
A2: ITEM | B2: VEÍCULO | C2: NOMENCLATURA | D2: QTD TR | E2: QTD EMPENHADO | F2: QTD DISPONÍVEL | G2: VALOR UNITÁRIO | H2: VALOR TOTAL | I2: OM RECEBEDORA | J2: MARCA | K2: CNPJ | L2: EMPRESA | M2: CONTATO | N2: EMAIL | O2: ATA | P2: VIGÊNCIA | Q2: OBS
A3: 1 | B3: P1-01A-DTS | C3: VEÍCULO ESPECIAL | D3: 4 | E3: 3 | F3: =D3-E3 -> 1 | G3: 159000 | H3: =D3*G3 -> 636000 | I3: GAP-RJ | J3: Toyota | K3: 59.104.760/0006-04 | L3: TOYOTA DO BRASIL | M3: (15) 99838-3299 | N3: danilo.massini@toyota.com.br
A4: 1 | B4: P1-01A-DTS | C4: VEÍCULO ESPECIAL | D4: 14 | E4: 12 | F4: =D4-E4 -> 2 | G4: 159000 | H4: =D4*G4 -> 2226000 | I4: GAB-BR | J4: Toyota | K4: 59.104.760/0006-04 | L4: TOYOTA DO BRASIL | M4: (15) 99838-3299 | N4: danilo.massini@toyota.com.br
A5: 1 | B5: P1-01A-DTS | C5: VEÍCULO ESPECIAL | D5: 2 | E5: 1 | F5: =D5-E5 -> 1 | G5: 159000 | H5: =D5*G5 -> 318000 | I5: GAP-SP | J5: Toyota | K5: 59.104.760/0006-04 | L5: TOYOTA DO BRASIL | M5: (15) 99838-3299 | N5: danilo.massini@toyota.com.br
A6: 2 | B6: P8-01A-DTS | C6: MOTOCICLETA NORMAL | D6: 1 | E6: 0 | F6: =D6-E6 -> 1 | H6: =D6*G6 -> 0 | I6: AFA | J6: FRACASADA
A7: 2 | B7: P8-01A-DTS | C7: MOTOCICLETA NORMAL | D7: 1 | E7: 0 | F7: =D7-E7 -> 1 | H7: =D7*G7 -> 0 | I7: BACG | J7: FRACASADA
A8: 2 | B8: P8-01A-DTS | C8: MOTOCICLETA NORMAL | D8: 1 | E8: 0 | F8: =D8-E8 -> 1 | H8: =D8*G8 -> 0 | I8: BAFL | J8: FRACASADA
A9: 2 | B9: P8-01A-DTS | C9: MOTOCICLETA NORMAL | D9: 1 | E9: 0 | F9: =D9-E9 -> 1 | H9: =D9*G9 -> 0 | I9: BANT | J9: FRACASADA
A10: 2 | B10: P8-01A-DTS | C10: MOTOCICLETA NORMAL | D10: 1 | E10: 0 | F10: =D10-E10 -> 1 | H10: =D10*G10 -> 0 | I10: BAPV | J10: FRACASADA
A11: 2 | B11: P8-01A-DTS | C11: MOTOCICLETA NORMAL | D11: 1 | E11: 0 | F11: =D11-E11 -> 1 | H11: =D11*G11 -> 0 | I11: BASV | J11: FRACASADA
A12: 2 | B12: P8-01A-DTS | C12: MOTOCICLETA NORMAL | D12: 1 | E12: 0 | F12: =D12-E12 -> 1 | H12: =D12*G12 -> 0 | I12: GAP-MN | J12: FRACASADA
A13: 2 | B13: P8-01A-DTS | C13: MOTOCICLETA NORMAL | D13: 1 | E13: 0 | F13: =D13-E13 -> 1 | H13: =D13*G13 -> 0 | I13: GAP-SP | J13: FRACASADA
A14: 3 | B14: P12-02A-DTS | C14: CARRO DE OPERAÇÕES | D14: 2 | E14: 1 | F14: =D14-E14 -> 1 | G14: 241590 | H14: =D14*G14 -> 483180 | I14: BASC | J14: MITSUBISHI | K14: 54.305.743/0011-70 | L14: HPE AUTOMOTORES DO BRASIL | M14: (11) 98167-5341 | N14: governo@almeidaesilva.com.br
A15: 3 | B15: P12-02A-DTS | C15: CARRO DE OPERAÇÕES | D15: 1 | E15: 1 | F15: =D15-E15 -> 0 | G15: 241590 | H15: =D15*G15 -> 241590 | I15: BASM | J15: MITSUBISHI | K15: 54.305.743/0011-70 | L15: HPE AUTOMOTORES DO BRASIL | M15: (11) 98167-5341 | N15: governo@almeidaesilva.com.br
A16: 3 | B16: P12-02A-DTS | C16: CARRO DE OPERAÇÕES | D16: 2 | E16: 1 | F16: =D16-E16 -> 1 | G16: 241590 | H16: =D16*G16 -> 483180 | I16: CINDACTA II | J16: MITSUBISHI | K16: 54.305.743/0011-70 | L16: HPE AUTOMOTORES DO BRASIL | M16: (11) 98167-5341 | N16: governo@almeidaesilva.com.br
A17: 3 | B17: P12-02A-DTS | C17: CARRO DE OPERAÇÕES | D17: 1 | E17: 0 | F17: =D17-E17 -> 1 | G17: 241590 | H17: =D17*G17 -> 241590 | I17: EPCAR | J17: MITSUBISHI | K17: 54.305.743/0011-70 | L17: HPE AUTOMOTORES DO BRASIL | M17: (11) 98167-5341 | N17: governo@almeidaesilva.com.br
A18: 3 | B18: P12-02A-DTS | C18: CARRO DE OPERAÇÕES | D18: 2 | E18: 1 | F18: =D18-E18 -> 1 | G18: 241590 | H18: =D18*G18 -> 483180 | I18: GAP-BE | J18: MITSUBISHI | K18: 54.305.743/0011-70 | L18: HPE AUTOMOTORES DO BRASIL | M18: (11) 98167-5341 | N18: governo@almeidaesilva.com.br
A19: 3 | B19: P12-02A-DTS | C19: CARRO DE OPERAÇÕES | D19: 1 | E19: 0 | F19: =D19-E19 -> 1 | G19: 241590 | H19: =D19*G19 -> 241590 | I19: GAP-RF | J19: MITSUBISHI | K19: 54.305.743/0011-70 | L19: HPE AUTOMOTORES DO BRASIL | M19: (11) 98167-5341 | N19: governo@almeidaesilva.com.br
A20: 3 | B20: P12-02A-DTS | C20: CARRO DE OPERAÇÕES | D20: 1 | E20: 0 | F20: =D20-E20 -> 1 | G20: 241590 | H20: =D20*G20 -> 241590 | I20: BANT | J20: MITSUBISHI | K20: 54.305.743/0011-70 | L20: HPE AUTOMOTORES DO BRASIL | M20: (11) 98167-5341 | N20: governo@almeidaesilva.com.br
A21: 3 | B21: P12-02A-DTS | C21: CARRO DE OPERAÇÕES | D21: 1 | E21: 0 | F21: =D21-E21 -> 1 | G21: 241590 | H21: =D21*G21 -> 241590 | I21: BASV | J21: MITSUBISHI | K21: 54.305.743/0011-70 | L21: HPE AUTOMOTORES DO BRASIL | M21: (11) 98167-5341 | N21: governo@almeidaesilva.com.br
A22: 3 | B22: P12-02A-DTS | C22: CARRO DE OPERAÇÕES | D22: 1 | E22: 1 | F22: =D22-E22 -> 0 | G22: 241590 | H22: =D22*G22 -> 241590 | I22: GAP-LS | J22: MITSUBISHI | K22: 54.305.743/0011-70 | L22: HPE AUTOMOTORES DO BRASIL | M22: (11) 98167-5341 | N22: governo@almeidaesilva.com.br
A23: 3 | B23: P12-02A-DTS | C23: CARRO DE OPERAÇÕES | D23: 2 | E23: 0 | F23: =D23-E23 -> 2 | G23: 241590 | H23: =D23*G23 -> 483180 | I23: GAP-SJ | J23: MITSUBISHI | K23: 54.305.743/0011-70 | L23: HPE AUTOMOTORES DO BRASIL | M23: (11) 98167-5341 | N23: governo@almeidaesilva.com.br
A24: 3 | B24: P12-02A-DTS | C24: CARRO DE OPERAÇÕES | D24: 1 | E24: 1 | F24: =D24-E24 -> 0 | G24: 241590 | H24: =D24*G24 -> 241590 | I24: COMARA | J24: MITSUBISHI | K24: 54.305.743/0011-70 | L24: HPE AUTOMOTORES DO BRASIL | M24: (11) 98167-5341 | N24: governo@almeidaesilva.com.br
A25: 3 | B25: P12-02A-DTS | C25: CARRO DE OPERAÇÕES | D25: 1 | E25: 0 | F25: =D25-E25 -> 1 | G25: 241590 | H25: =D25*G25 -> 241590 | I25: BACG | J25: MITSUBISHI | K25: 54.305.743/0011-70 | L25: HPE AUTOMOTORES DO BRASIL | M25: (11) 98167-5341 | N25: governo@almeidaesilva.com.br
... A29: 3 | B29: P12-02A-DTS | C29: CARRO DE OPERAÇÕES | D29: 1 | E29: 0 | F29: =D29-E29 -> 1 | G29: 241590 | H29: =D29*G29 -> 241590 | I29: GAP-GL | J29: MITSUBISHI | K29: 54.305.743/0011-70 | L29: HPE AUTOMOTORES DO BRASIL | M29: (11) 98167-5341 | N29: governo@almeidaesilva.com.br
A30: 4 | B30: C4-01A-DTS | C30: FURGÃO LEVE | D30: 4 | E30: 0 | F30: =D30-E30 -> 4 | H30: =D30*G30 -> 0 | I30: GAP-AF | J30: fracassado
A31: 4 | B31: C4-01A-DTS | C31: FURGÃO LEVE | D31: 2 | E31: 0 | F31: =D31-E31 -> 2 | H31: =D31*G31 -> 0 | I31: BAPV | J31: fracassado
A32: 4 | B32: C4-01A-DTS | C32: FURGÃO LEVE | D32: 2 | E32: 0 | F32: =D32-E32 -> 2 | H32: =D32*G32 -> 0 | I32: GAP-RF | J32: fracassado
A33: 4 | B33: C4-01A-DTS | C33: FURGÃO LEVE | D33: 4 | E33: 0 | F33: =D33-E33 -> 4 | H33: =D33*G33 -> 0 | I33: GAP-SJ | J33: fracassado

Sheet 90186_2024
A1: PAG | B1: 67.106.001809/2024-27 | C1: STATUS em 24/10/24:
A2: ITEM | B2: VEÍCULO | C2: NOMENCLATURA | D2: QTD TR | E2: QTD EMPENHADO | F2: QNT DISPONÍVEL | G2: VALOR UNITÁRIO | H2: VALOR TOTAL | I2: OM RECEBEDORA | J2: MARCA/MODELO | K2: CNPJ | L2: EMPRESA | M2: CONTATO | N2: EMAIL | O2: ATA | P2: VIGÊNCIA | Q2: OBS | R2: Coluna1
A3: 1 | B3: C-5/02A/DTS | C3: CAMINHÃO BAÚ | D3: 1 | E3: 1 | F3: =D3-E3 -> 0 | G3: 574575 | H3: =G3*D3 -> 574575 | I3: CINDACTA 2 | J3: VOLVO / VM | K3: 03.093.776/0018-30 | L3: MANUPA COMERCIO EXPORTACAO IMPORTACAO DE EQUIPAMENTOS E VEICULOS ADAPTADOS LTDA | P3: 45975 | Q3: HOMOLOGADO
A4: 1 | B4: C-5/02A/DTS | C4: CAMINHÃO BAÚ | D4: 1 | E4: 1 | F4: =D4-E4 -> 0 | G4: 574575 | H4: =G4*D4 -> 574575 | I4: CINDACTA 4 | J4: VOLVO / VM | K4: 03.093.776/0018-30 | L4: MANUPA COMERCIO EXPORTACAO IMPORTACAO DE EQUIPAMENTOS E VEICULOS ADAPTADOS LTDA | P4: 45975 | Q4: HOMOLOGADO
A5: 1 | B5: C-5/02A/DTS | C5: CAMINHÃO BAÚ | D5: 1 | E5: 0 | F5: =D5-E5 -> 1 | G5: 574575 | H5: =G5*D5 -> 574575 | I5: CRCEA-SE | J5: VOLVO / VM | K5: 03.093.776/0018-30 | L5: MANUPA COMERCIO EXPORTACAO IMPORTACAO DE EQUIPAMENTOS E VEICULOS ADAPTADOS LTDA | P5: 45975 | Q5: HOMOLOGADO
A6: 1 | B6: C-5/02A/DTS | C6: CAMINHÃO BAÚ | D6: 1 | E6: 1 | F6: =D6-E6 -> 0 | G6: 574575 | H6: =G6*D6 -> 574575 | I6: DECEA | J6: VOLVO / VM | K6: 03.093.776/0018-30 | L6: MANUPA COMERCIO EXPORTACAO IMPORTACAO DE EQUIPAMENTOS E VEICULOS ADAPTADOS LTDA | P6: 45975 | Q6: HOMOLOGADO
A7: 1 | B7: C-5/02A/DTS | C7: CAMINHÃO BAÚ | D7: 1 | E7: 1 | F7: =D7-E7 -> 0 | G7: 574575 | H7: =G7*D7 -> 574575 | I7: GABAER | J7: VOLVO / VM | K7: 03.093.776/0018-30 | L7: MANUPA COMERCIO EXPORTACAO IMPORTACAO DE EQUIPAMENTOS E VEICULOS ADAPTADOS LTDA | P7: 45975 | Q7: HOMOLOGADO
A8: 2 | B8: C-8-01A-DTS | C8: CAMINHÃO BAÚ TRUCADO | D8: 4 | E8: 4 | F8: =D8-E8 -> 0 | G8: 659633.19 | H8: =G8*D8 -> 2638532.8 | I8: GAP-AF | J8: VOLVO | K8: 03.093.776/0018-30 | L8: MANUPA | P8: 45975 | Q8: HOMOLOGADO
A9: 3 | B9: E-16-01A-DTS | C9: CAMINHÃO EQUIPADO COM ELEVADOR HIDRÁULICO E CESTO AÉREO | D9: 1 | E9: 0 | F9: =D9-E9 -> 1 | G9: 558500 | H9: =G9*D9 -> 558500 | I9: GAP-DF | J9: MERCEDES-BENS | K9: 08.206.867/0001-00 | L9: ECS COMERCIO DE VEICULOS | Q9: HOMOLOGADO
A10: 3 | B10: E-16-01A-DTS | C10: CAMINHÃO EQUIPADO COM ELEVADOR HIDRÁULICO E CESTO AÉREO | D10: 1 | E10: 1 | F10: =D10-E10 -> 0 | G10: 558500 | H10: =G10*D10 -> 558500 | I10: GAP-GL | J10: MERCEDES-BENS | K10: 03.093.776/0018-30 | L10: ECS COMERCIO DE VEICULOS | M10: (62) 9 9145-5883 | N10: temporarioforza@gmail.com | Q10: HOMOLOGADO
A11: 4 | B11: E-15-01A-DTS | C11: CAMINHÃO EQUIPADO COM GUINDASTE HIDRÁULICO | D11: 1 | E11: 0 | F11: =D11-E11 -> 1 | G11: 979500 | H11: =G11*D11 -> 979500 | I11: CINDACTA 1 | J11: VOLVO | K11: 46.135.499/0001-45 | L11: FORZA DISTRIBUIDORA LTDA | M11: (62) 9 9145-5883 | N11: temporarioforza@gmail.com | Q11: HOMOLOGADO VENCEDOR NOVO HORIZONTE ITEM REABERTO
A12: 4 | B12: E-15-01A-DTS | C12: CAMINHÃO EQUIPADO COM GUINDASTE HIDRÁULICO | D12: 1 | E12: 0 | F12: =D12-E12 -> 1 | G12: 979500 | H12: =G12*D12 -> 979500 | I12: CINDACTA 2 | J12: VOLVO | K12: 46.135.499/0001-45 | L12: FORZA DISTRIBUIDORA LTDA | M12: (62) 9 9145-5883 | N12: temporarioforza@gmail.com | Q12: HOMOLOGADO VENCEDOR NOVO HORIZONTE ITEM REABERTO
A13: 4 | B13: E-15-01A-DTS | C13: CAMINHÃO EQUIPADO COM GUINDASTE HIDRÁULICO | D13: 1 | E13: 0 | F13: =D13-E13 -> 1 | G13: 979500 | H13: =G13*D13 -> 979500 | I13: CINDACTA 3 | J13: VOLVO | K13: 46.135.499/0001-45 | L13: FORZA DISTRIBUIDORA LTDA | M13: (62) 9 9145-5883 | N13: temporarioforza@gmail.com | Q13: HOMOLOGADO VENCEDOR NOVO HORIZONTE ITEM REABERTO
A14: 4 | B14: E-15-01A-DTS | C14: CAMINHÃO EQUIPADO COM GUINDASTE HIDRÁULICO | D14: 1 | E14: 0 | F14: =D14-E14 -> 1 | G14: 979500 | H14: =G14*D14 -> 979500 | I14: GAP-BE | J14: VOLVO | K14: 46.135.499/0001-45 | L14: FORZA DISTRIBUIDORA LTDA | M14: (62) 9 9145-5883 | N14: temporarioforza@gmail.com | Q14: HOMOLOGADO VENCEDOR NOVO HORIZONTE ITEM REABERTO
A15: 5 | B15: C-1-01A-DTS | C15: CAMINHÃO LEVE | D15: 1 | E15: 1 | F15: =D15-E15 -> 0 | G15: 364128.52 | H15: =G15*D15 -> 364128.52 | I15: CINDACTA 1 | J15: Foton Aumark 916 | K15: 03.093.776/0018-30 | L15: MANUPA COMERCIO EXPORTACAO IMPORTACAO DE EQUIPAMENTOS E VEICULOS ADAPTADOS LTDA | Q15: HOMOLOGADO
A16: 5 | B16: C-1-01A-DTS | C16: CAMINHÃO LEVE | D16: 1 | E16: 1 | F16: =D16-E16 -> 0 | G16: 364128.52 | H16: =G16*D16 -> 364128.52 | I16: CINDACTA3 | J16: Foton Aumark 916 | K16: 03.093.776/0018-30 | L16: MANUPA COMERCIO EXPORTACAO IMPORTACAO DE EQUIPAMENTOS E VEICULOS ADAPTADOS LTDA | Q16: HOMOLOGADO
A17: 5 | B17: C-1-01A-DTS | C17: CAMINHÃO LEVE | D17: 3 | E17: 3 | F17: =D17-E17 -> 0 | G17: 364128.52 | H17: =G17*D17 -> 1092385.6 | I17: COMARA | J17: Foton Aumark 916 | K17: 03.093.776/0018-30 | L17: MANUPA COMERCIO EXPORTACAO IMPORTACAO DE EQUIPAMENTOS E VEICULOS ADAPTADOS LTDA | Q17: HOMOLOGADO
A18: 5 | B18: C-1-01A-DTS | C18: CAMINHÃO LEVE | D18: 1 | E18: 0 | F18: =D18-E18 -> 1 | G18: 364128.52 | H18: =G18*D18 -> 364128.52 | I18: GAP-GL | J18: Foton Aumark 916 | K18: 03.093.776/0018-30 | L18: MANUPA COMERCIO EXPORTACAO IMPORTACAO DE EQUIPAMENTOS E VEICULOS ADAPTADOS LTDA | P18: 46003 | Q18: HOMOLOGADO
A19: 6 | B19: C-2-01A-DTS | C19: CAMINHÃO MÉDIO/PESADO | D19: 1 | E19: 0 | F19: =D19-E19 -> 1 | G19: 517000 | H19: =G19*D19 -> 517000 | I19: BANT | J19: Volkswagen Truck & bus / 14210 com carroceria metalica | K19: 11.726.521/0001-47 | L19: TRANSRIO CAMINHOES, ONIBUS, MAQUINAS E MOTORES LTDA | P19: 45975 | Q19: HOMOLOGADO
A20: 6 | B20: C-2-01A-DTS | C20: CAMINHÃO MÉDIO/PESADO | D20: 1 | E20: 1 | F20: =D20-E20 -> 0 | G20: 517000 | H20: =G20*D20 -> 517000 | I20: CRCEA-SE | J20: Volkswagen Truck & bus / 14210 com carroceria metalica | K20: 11.726.521/0001-47 | L20: TRANSRIO CAMINHOES, ONIBUS, MAQUINAS E MOTORES LTDA | P20: 45975 | Q20: HOMOLOGADO
A21: 7 | B21: P-7-01A-DTS | C21: CAMINHÃO MILITAR | D21: 1 | E21: 0 | F21: =D21-E21 -> 1 | G21: 880000 | H21: =G21*D21 -> 880000 | I21: GAP-AF | J21: VOLKSWAGEN 11180 4X4 | K21: 03.093.776/0018-30 | L21: TRANSRIO CAMINHOES, ONIBUS, MAQUINAS E MOTORES LTDA | P21: 46007 | Q21: Julgado e habilitado (aberto para recursos)
A22: 7 | B22: P-7-01A-DTS | C22: CAMINHÃO MILITAR | D22: 1 | E22: 0 | F22: =D22-E22 -> 1 | G22: 880000 | H22: =G22*D22 -> 880000 | I22: GAP-BE | J22: VOLKSWAGEN 11180 4X4 | K22: 03.093.776/0018-30 | L22: TRANSRIO CAMINHOES, ONIBUS, MAQUINAS E MOTORES LTDA | P22: 46007 | Q22: Julgado e habilitado (aberto para recursos)
A23: 7 | B23: P-7-01A-DTS | C23: CAMINHÃO MILITAR | D23: 1 | E23: 0 | F23: =D23-E23 -> 1 | G23: 880000 | H23: =G23*D23 -> 880000 | I23: GAP-CO | J23: VOLKSWAGEN 11180 4X4 | K23: 03.093.776/0018-30 | L23: TRANSRIO CAMINHOES, ONIBUS, MAQUINAS E MOTORES LTDA | P23: 46007 | Q23: Julgado e habilitado (aberto para recursos)
A24: 7 | B24: P-7-01A-DTS | C24: CAMINHÃO MILITAR | D24: 1 | E24: 0 | F24: =D24-E24 -> 1 | G24: 880000 | H24: =G24*D24 -> 880000 | I24: GAP-DF | J24: VOLKSWAGEN 11180 4X4 | K24: 03.093.776/0018-30 | L24: TRANSRIO CAMINHOES, ONIBUS, MAQUINAS E MOTORES LTDA | P24: 46007 | Q24: Julgado e habilitado (aberto para recursos)
A25: 7 | B25: P-7-01A-DTS | C25: CAMINHÃO MILITAR | D25: 1 | E25: 0 | F25: =D25-E25 -> 1 | G25: 880000 | H25: =G25*D25 -> 880000 | I25: GAP-GL | J25: VOLKSWAGEN 11180 4X4 | K25: 03.093.776/0018-30 | L25: TRANSRIO CAMINHOES, ONIBUS, MAQUINAS E MOTORES LTDA | P25: 46007 | Q25: Julgado e habilitado (aberto para recursos)
A26: 7 | B26: P-7-01A-DTS | C26: CAMINHÃO MILITAR | D26: 1 | E26: 0 | F26: =D26-E26 -> 1 | G26: 880000 | H26: =G26*D26 -> 880000 | I26: GAP-MN | J26: VOLKSWAGEN 11180 4X4 | K26: 03.093.776/0018-30 | L26: TRANSRIO CAMINHOES, ONIBUS, MAQUINAS E MOTORES LTDA | P26: 46007 | Q26: Julgado e habilitado (aberto para recursos)
A27: 7 | B27: P-7-01A-DTS | C27: CAMINHÃO MILITAR | D27: 1 | E27: 0 | F27: =D27-E27 -> 1 | G27: 880000 | H27: =G27*D27 -> 880000 | I27: GAP-RF | J27: VOLKSWAGEN 11180 4X4 | K27: 03.093.776/0018-30 | L27: TRANSRIO CAMINHOES, ONIBUS, MAQUINAS E MOTORES LTDA | P27: 46007 | Q27: Julgado e habilitado (aberto para recursos)
A28: 7 | B28: P-7-01A-DTS | C28: CAMINHÃO MILITAR | D28: 1 | E28: 0 | F28: =D28-E28 -> 1 | G28: 880000 | H28: =G28*D28 -> 880000 | I28: BANT | J28: VOLKSWAGEN 11180 4X4 | K28: 03.093.776/0018-30 | L28: TRANSRIO CAMINHOES, ONIBUS, MAQUINAS E MOTORES LTDA | P28: 46007 | Q28: Julgado e habilitado (aberto para recursos)
A29: 7 | B29: P-7-01A-DTS | C29: CAMINHÃO MILITAR | D29: 1 | E29: 0 | F29: =D29-E29 -> 1 | G29: 880000 | H29: =G29*D29 -> 880000 | I29: GAP-RJ | J29: VOLKSWAGEN 11180 4X4 | K29: 03.093.776/0018-30 | L29: TRANSRIO CAMINHOES, ONIBUS, MAQUINAS E MOTORES LTDA | P29: 46007 | Q29: Julgado e habilitado (aberto para recursos)
A30: 7 | B30: P-7-01A-DTS | C30: CAMINHÃO MILITAR | D30: 1 | E30: 0 | F30: =D30-E30 -> 1 | G30: 880000 | H30: =G30*D30 -> 880000 | I30: GAP-SJ | J30: VOLKSWAGEN 11180 4X4 | K30: 03.093.776/0018-30 | L30: TRANSRIO CAMINHOES, ONIBUS, MAQUINAS E MOTORES LTDA | P30: 46007 | Q30: Julgado e habilitado (aberto para recursos)
A31: 7 | B31: P-7-01A-DTS | C31: CAMINHÃO MILITAR | D31: 1 | E31: 0 | F31: =D31-E31 -> 1 | G31: 880000 | H31: =G31*D31 -> 880000 | I31: GAP-SP | J31: VOLKSWAGEN 11180 4X4 | K31: 03.093.776/0018-30 | L31: TRANSRIO CAMINHOES, ONIBUS, MAQUINAS E MOTORES LTDA | Q31: Julgado e habilitado (aberto para recursos)
A32: 8 | B32: C-7-01A-DTS | C32: CAMINHÃO TRUCADO | D32: 1 | E32: 0 | F32: =D32-E32 -> 1 | G32: 594480 | H32: =G32*D32 -> 594480 | I32: PAME-RJ | J32: MERCEDES-BENS/ ATEGO 2429 | K32: 08.206.867/0001-00 | L32: ECS COMERCIO DE VEICULOS E EQUIPAMENTOS LTDA | P32: 45975 | Q32: HOMOLOGADO
A33: 9 | B33: P-19-01A-DTS | C33: CAMINHONETE MILITAR | D33: 1 | E33: 0 | F33: =D33-E33 -> 1 | G33: 617000 | H33: =G33*D33 -> 617000 | I33: AFA | J33: AGRALE MARRUÁ AM23 G2 - MILITAR | K33: 88.610.324/0001-92 | L33: AGRALE | Q33: Aguardando julgamento
A34: 9 | B34: P-19-01A-DTS | C34: CAMINHONETE MILITAR | D34: 2 | E34: 0 | F34: =D34-E34 -> 2 | G34: 617000 | H34: =G34*D34 -> 1234000 | I34: BAAN | J34: AGRALE MARRUÁ AM23 G2 - MILITAR | K34: 88.610.324/0001-92 | L34: AGRALE | Q34: Aguardando julgamento
A35: 9 | B35: P-19-01A-DTS | C35: CAMINHONETE MILITAR | D35: 2 | E35: 0 | F35: =D35-E35 -> 2 | G35: 617000 | H35: =G35*D35 -> 1234000 | I35: BACG | J35: AGRALE MARRUÁ AM23 G2 - MILITAR | K35: 88.610.324/0001-92 | L35: AGRALE | Q35: Aguardando julgamento
A36: 9 | B36: P-19-01A-DTS | C36: CAMINHONETE MILITAR | D36: 1 | E36: 0 | F36: =D36-E36 -> 1 | G36: 617000 | H36: =G36*D36 -> 617000 | I36: CPBV | J36: AGRALE MARRUÁ AM23 G2 - MILITAR | K36: 88.610.324/0001-92 | L36: AGRALE | Q36: Aguardando julgamento
A37: 9 | B37: P-19-01A-DTS | C37: CAMINHONETE MILITAR | D37: 2 | E37: 0 | F37: =D37-E37 -> 2 | G37: 617000 | H37: =G37*D37 -> 1234000 | I37: GAP-CO | J37: AGRALE MARRUÁ AM23 G2 - MILITAR | K37: 88.610.324/0001-92 | L37: AGRALE | Q37: Aguardando julgamento
A38: 9 | B38: P-19-01A-DTS | C38: CAMINHONETE MILITAR | D38: 2 | E38: 0 | F38: =D38-E38 -> 2 | G38: 617000 | H38: =G38*D38 -> 1234000 | I38: GAP-MN | J38: AGRALE MARRUÁ AM23 G2 - MILITAR | K38: 88.610.324/0001-92 | L38: AGRALE | Q38: Aguardando julgamento
A39: 10 | B39: P-12-02A-DTS | C39: CARRO DE OPERAÇÕES | D39: 1 | E39: 1 | F39: ='90186_2024'!$D39-'90186_2024'!$E39 -> 0 | G39: 244000 | H39: =G39*D39 -> 244000 | I39: BABV | J39: MITSUBISHI / L200 TRITON GL | K39: 54.305.743/0011-70 | L39: HPE AUTOMOTORES DO BRASIL LTDA | P39: 45975 | Q39: HOMOLOGADO
A40: 10 | B40: P-12-02A-DTS | C40: CARRO DE OPERAÇÕES | D40: 1 | E40: 1 | F40: ='90186_2024'!$D40-'90186_2024'!$E40 -> 0 | G40: 244000 | H40: =G40*D40 -> 244000 | I40: CINDACTA 4 | J40: MITSUBISHI / L200 TRITON GL | K40: 54.305.743/0011-70 | L40: HPE AUTOMOTORES DO BRASIL LTDA | P40: 45975 | Q40: HOMOLOGADO
...

Sheet 90103_2024
A1: PAG | B1: 67106.000741/2024-69 | C1: STATUS em 07/10/24 item 1 homologado; item 2 fracassado | F1: VIGÊNCIA ENCERRADA
A2: ITEM | B2: VEÍCULO | C2: NOMENCLATURA | D2: QTD TR | E2: QTD EMPENHADO | F2: QTD DISPONÍVEL | G2: VALOR UNITÁRIO | H2: VALOR TOTAL | I2: OM RECEBEDORA | J2: MARCA/MODELO | K2: CNPJ | L2: EMPRESA | M2: CONTATO | N2: EMAIL | O2: ATA | P2: VIGÊNCIA | Q2: OBS
A3: 1 | B3: P-1/02A/DTS | C3: VEÍCULO ESPECIAL | D3: 2 | E3: 2 | F3: 0 | G3: 97500 | H3: =D3*G3 -> 195000 | I3: CINDACTA 4 | J3: FIAT - CRONOS DRIVE 1.3 FLEX 4P 2025 | K3: 16.701.716/0001-56 | L3: FCA Fiat Chrysler Automóveis Brasil Ltda | M3: (41) 99228 3904 | N3: antonio.menna@stellantis.com | O3: 01253/2024 | P3: 06/08/2024 a 05/08/2025
A4: 1 | B4: P-1/02A/DTS | C4: VEÍCULO ESPECIAL | D4: 2 | E4: 2 | F4: 0 | G4: 97500 | H4: =D4*G4 -> 195000 | I4: CRCEA-SE | J4: FIAT - CRONOS DRIVE 1.3 FLEX 4P 2025 | K4: 16.701.716/0001-56 | L4: FCA Fiat Chrysler Automóveis Brasil Ltda | M4: (41) 99228 3904 | N4: antonio.menna@stellantis.com | O4: 01253/2024 | P4: 06/08/2024 a 05/08/2025
A5: 1 | B5: P-1/02A/DTS | C5: VEÍCULO ESPECIAL | D5: 5 | E5: 5 | F5: 0 | G5: 97500 | H5: =D5*G5 -> 487500 | I5: GAP-RJ | J5: FIAT - CRONOS DRIVE 1.3 FLEX 4P 2025 | K5: 16.701.716/0001-56 | L5: FCA Fiat Chrysler Automóveis Brasil Ltda | M5: (41) 99228 3904 | N5: antonio.menna@stellantis.com | O5: 01253/2024 | P5: 06/08/2024 a 05/08/2025
A6: 1 | B6: P-1/02A/DTS | C6: VEÍCULO ESPECIAL | D6: 1 | E6: 1 | F6: 0 | G6: 97500 | H6: =D6*G6 -> 97500 | I6: GAP-CO | J6: FIAT - CRONOS DRIVE 1.3 FLEX 4P 2025 | K6: 16.701.716/0001-56 | L6: FCA Fiat Chrysler Automóveis Brasil Ltda | M6: (41) 99228 3904 | N6: antonio.menna@stellantis.com | O6: 01253/2024 | P6: 06/08/2024 a 05/08/2025
A7: 1 | B7: P-1/02A/DTS | C7: VEÍCULO ESPECIAL | D7: 1 | E7: 1 | F7: 0 | G7: 97500 | H7: =D7*G7 -> 97500 | I7: GAP-MN | J7: FIAT - CRONOS DRIVE 1.3 FLEX 4P 2025 | K7: 16.701.716/0001-56 | L7: FCA Fiat Chrysler Automóveis Brasil Ltda | M7: (41) 99228 3904 | N7: antonio.menna@stellantis.com | O7: 01253/2024 | P7: 06/08/2024 a 05/08/2025
A8: 2 | B8: P-10/01A/DTS | C8: MOTOCICLETA TRAIL | D8: 1 | E8: 0 | F8: 0 | G8: FRACASSADO | H8: FRACASSADO | I8: BANT | J8: x | K8: x | L8: x | M8: x | N8: x | O8: x | P8: x | Q8: x

Sheet 90060_2024
B1: 67106.000741/2024-69 | C1: VIGÊNCIA ENCERRADA
A2: 1 | B2: C-2/01A/DTS | C2: CAMINHÃO MÉDIO PESADO | D2: 1 | E2: 0 | F2: =D2-E2 -> 1 | G2: REVOGADO | H2: REVOGADO | I2: BANT | J2: x | K2: x | L2: x | M2: x | N2: x | O2: x | P2: x | Q2: x
A3: 2 | B3: C-4/01A/DTS | C3: FURGÃO LEVE | D3: 1 | E3: 1 | F3: =D3-E3 -> 0 | G3: 118000 | H3: ='90060_2024'!$D3*'90060_2024'!$G3 -> 118000 | I3: DECEA | J3: FIAT FIORINO ENDURANCE 1.4 FLEX 2024/2024 | K3: 23.821.956/0001-50 | L3: DINAMICA | M3: (62) 99139-5151 | N3: contato@comercialdinamica.com.br | O3: 1192 | P3: 45847
A4: 2 | B4: C-4/01A/DTS | C4: FURGÃO LEVE | D4: 1 | E4: 1 | F4: =D4-E4 -> 0 | G4: 118000 | H4: ='90060_2024'!$D4*'90060_2024'!$G4 -> 118000 | I4: BACG | J4: FIAT FIORINO ENDURANCE 1.4 FLEX 2024/2025 | K4: 23.821.956/0001-50 | L4: DINAMICA | M4: (62) 99139-5151 | N4: contato@comercialdinamica.com.br | O4: 1192 | P4: 45847
A5: 2 | B5: C-4/01A/DTS | C5: FURGÃO LEVE | D5: 1 | E5: 1 | F5: =D5-E5 -> 0 | G5: 118000 | H5: ='90060_2024'!$D5*'90060_2024'!$G5 -> 118000 | I5: BAPV | J5: FIAT FIORINO ENDURANCE 1.4 FLEX 2024/2026 | K5: 23.821.956/0001-50 | L5: DINAMICA | M5: (62) 99139-5151 | N5: contato@comercialdinamica.com.br | O5: 1192 | P5: 45847
A6: 2 | B6: C-4/01A/DTS | C6: FURGÃO LEVE | D6: 3 | E6: 2 | F6: =D6-E6 -> 1 | G6: 118000 | H6: ='90060_2024'!$D6*'90060_2024'!$G6 -> 354000 | I6: CINDACTA 3 | J6: FIAT FIORINO ENDURANCE 1.4 FLEX 2024/2027 | K6: 23.821.956/0001-50 | L6: DINAMICA | M6: (62) 99139-5151 | N6: contato@comercialdinamica.com.br | O6: 1192 | P6: 45847
A7: 2 | B7: C-4/01A/DTS | C7: FURGÃO LEVE | D7: 2 | E7: 2 | F7: =D7-E7 -> 0 | G7: 118000 | H7: ='90060_2024'!$D7*'90060_2024'!$G7 -> 236000 | I7: BANT | J7: FIAT FIORINO ENDURANCE 1.4 FLEX 2024/2028 | K7: 23.821.956/0001-50 | L7: DINAMICA | M7: (62) 99139-5151 | N7: contato@comercialdinamica.com.br | O7: 1192 | P7: 45847
A8: 3 | B8: C-6/01A/DTS | C8: PICK UP CABINE SIMPLES | D8: 3 | E8: 3 | F8: =D8-E8 -> 0 | G8: 109400 | H8: ='90060_2024'!$D8*'90060_2024'!$G8 -> 328200 | I8: CINDACTA 3 | J8: FIAT STRADA ENDURANCE CABINE PLUS/SIMPLES 1.3 FLEX 2024/2024 | K8: 23.821.956/0001-50 | L8: DINAMICA | M8: (62) 99139-5151 | N8: contato@comercialdinamica.com.br | O8: 1192 | P8: 45847
A9: 3 | B9: C-6/01A/DTS | C9: PICK UP CABINE SIMPLES | D9: 1 | E9: 1 | F9: =D9-E9 -> 0 | G9: 109400 | H9: ='90060_2024'!$D9*'90060_2024'!$G9 -> 109400 | I9: CLA | J9: FIAT STRADA ENDURANCE CABINE PLUS/SIMPLES 1.3 FLEX 2024/2024 | K9: 23.821.956/0001-50 | L9: DINAMICA | M9: (62) 99139-5151 | N9: contato@comercialdinamica.com.br | O9: 1192 | P9: 45847
A10: 3 | B10: C-6/01A/DTS | C10: PICK UP CABINE SIMPLES | D10: 1 | E10: 1 | F10: =D10-E10 -> 0 | G10: 109400 | H10: ='90060_2024'!$D10*'90060_2024'!$G10 -> 109400 | I10: GAP-RF | J10: FIAT STRADA ENDURANCE CABINE PLUS/SIMPLES 1.3 FLEX 2024/2024 | K10: 23.821.956/0001-50 | L10: DINAMICA | M10: (62) 99139-5151 | N10: contato@comercialdinamica.com.br | O10: 1192 | P10: 45847
A11: 3 | B11: C-6/01A/DTS | C11: PICK UP CABINE SIMPLES | D11: 1 | E11: 1 | F11: =D11-E11 -> 0 | G11: 109400 | H11: ='90060_2024'!$D11*'90060_2024'!$G11 -> 109400 | I11: BANT | J11: FIAT STRADA ENDURANCE CABINE PLUS/SIMPLES 1.3 FLEX 2024/2024 | K11: 23.821.956/0001-50 | L11: DINAMICA | M11: (62) 99139-5151 | N11: contato@comercialdinamica.com.br | O11: 1192 | P11: 45847
A12: 4 | B12: E-1/01A/DTS | C12: AMBULÂNCIA DE SUPORTE BÁSICO DE VIDA | D12: 1 | E12: 0 | F12: =D12-E12 -> 1 | G12: 349800 | H12: ='90060_2024'!$D12*'90060_2024'!$G12 -> 349800 | I12: BANT | J12: FORD TRANSIT / L3H3 | K12: 03.093.776/0018-30 | L12: MANUPA | M12: (11) 2478-2818 | N12: vg@manupa.com.br manupa@manupa.com.br | O12: 1190/2024 | P12: 45834
A13: 5 | B13: E-6/01A/DTS | C13: CARRO DE COLETOR | D13: 1 | E13: 0 | F13: x | G13: REVOGADO | H13: REVOGADO | I13: BANT | J13: x | K13: x | L13: x | M13: x | N13: x | O13: x | P13: x | Q13: x
A14: 6 | B14: E-10/02A/DTS | C14: EMPILHADEIRA | D14: 1 | E14: 0 | F14: =D14-E14 -> 1 | G14: 124899 | H14: ='90060_2024'!$D14*'90060_2024'!$G14 -> 124899 | I14: DECEA | J14: FABRICANTE: HANGCHA/ MODELO NACIONALIZADO MARCA: HANGCHA/ MOVIX MODELO: CPCD25/ MD25 | K14: 10.346.806/0001-90 | L14: MOVIX | M14: (54) 3342-9850 | N14: licitacao@movix.ind.br | O14: 1196 | P14: 45834
A15: 6 | B15: E-10/02A/DTS | C15: EMPILHADEIRA | D15: 1 | E15: 0 | F15: =D15-E15 -> 1 | G15: 124899 | H15: ='90060_2024'!$D15*'90060_2024'!$G15 -> 124899 | I15: CINDACTA 2 | J15: FABRICANTE: HANGCHA/ MODELO NACIONALIZADO MARCA: HANGCHA/ MOVIX MODELO: CPCD25/ MD25 | K15: 10.346.806/0001-90 | L15: MOVIX | M15: (54) 3342-9850 | N15: licitacao@movix.ind.br | O15: 1196 | P15: 45834
A16: 6 | B16: E-10/02A/DTS | C16: EMPILHADEIRA | D16: 4 | E16: 0 | F16: =D16-E16 -> 4 | G16: 124899 | H16: ='90060_2024'!$D16*'90060_2024'!$G16 -> 499596 | I16: CINDACTA 3 | J16: FABRICANTE: HANGCHA/ MODELO NACIONALIZADO MARCA: HANGCHA/ MOVIX MODELO: CPCD25/ MD25 | K16: 10.346.806/0001-90 | L16: MOVIX | M16: (54) 3342-9850 | N16: licitacao@movix.ind.br | O16: 1196 | P16: 45834
A17: 6 | B17: E-10/02A/DTS | C17: EMPILHADEIRA | D17: 1 | E17: 0 | F17: =D17-E17 -> 1 | G17: 124899 | H17: ='90060_2024'!$D17*'90060_2024'!$G17 -> 124899 | I17: CINDACTA 4 | J17: FABRICANTE: HANGCHA/ MODELO NACIONALIZADO MARCA: HANGCHA/ MOVIX MODELO: CPCD25/ MD25 | K17: 10.346.806/0001-90 | L17: MOVIX | M17: (54) 3342-9850 | N17: licitacao@movix.ind.br | O17: 1196 | P17: 45834
A18: 6 | B18: E-10/02A/DTS | C18: EMPILHADEIRA | D18: 1 | E18: 0 | F18: =D18-E18 -> 1 | G18: 124899 | H18: ='90060_2024'!$D18*'90060_2024'!$G18 -> 124899 | I18: CRCEA-SE | J18: FABRICANTE: HANGCHA/ MODELO NACIONALIZADO MARCA: HANGCHA/ MOVIX MODELO: CPCD25/ MD25 | K18: 10.346.806/0001-90 | L18: MOVIX | M18: (54) 3342-9850 | N18: licitacao@movix.ind.br | O18: 1196 | P18: 45834
A19: 7 | B19: E-11/02A/DTS | C19: TRATOR INDUSTRIAL | D19: 1 | E19: 0 | F19: =D19-E19 -> 1 | G19: FRACASSADO | H19: FRACASSADO | I19: BANT | J19: x | K19: x | L19: x | M19: x | N19: x | O19: x | P19: x | Q19: x
A20: 8 | B20: E-12/02B/DTS | C20: TRATOR DE RODAS COM ROÇADEIRA | D20: 2 | E20: 2 | F20: =D20-E20 -> 0 | G20: 177002.58 | H20: ='90060_2024'!$D20*'90060_2024'!$G20 -> 354005.16 | I20: BANT | J20: MAHINDRA 6075 / MFW ROTD 1800 | K20: 29.211.016/0002-06 | L20: DNM - DISTRIBUIDORA NACIONAL DE MAQUINAS LTDA | M20: (61) 99836-0434 | N20: DNMmaquinas@gmail.com | O20: 1197 | P20: 45840
A21: 8 | B21: E-12/02B/DTS | C21: TRATOR DE RODAS COM ROÇADEIRA | D21: 4 | E21: 4 | F21: =D21-E21 -> 0 | G21: 177002.58 | H21: ='90060_2024'!$D21*'90060_2024'!$G21 -> 708010.32 | I21: CINDACTA 3 | J21: MAHINDRA 6075 / MFW ROTD 1801 | K21: 29.211.016/0002-07 | L21: DNM - DISTRIBUIDORA NACIONAL DE MAQUINAS LTDA | M21: (61) 99836-0434 | N21: DNMmaquinas@gmail.com | O21: 1197 | P21: 45840
A22: 8 | B22: E-12/02B/DTS | C22: TRATOR DE RODAS COM ROÇADEIRA | D22: 1 | E22: 1 | F22: =D22-E22 -> 0 | G22: 177002.58 | H22: ='90060_2024'!$D22*'90060_2024'!$G22 -> 177002.58 | I22: GAP-MN | J22: MAHINDRA 6075 / MFW ROTD 1802 | K22: 29.211.016/0002-08 | L22: DNM - DISTRIBUIDORA NACIONAL DE MAQUINAS LTDA | M22: (61) 99836-0434 | N22: DNMmaquinas@gmail.com | O22: 1197 | P22: 45840
A23: ITEM | B23: VEÍCULO | C23: NOMENCLATURA | D23: QTD TR | E23: QNT EMPENHADO | F23: QNT DISPONÍVEL | G23: VALOR UNITÁRIO | H23: VALOR TOTAL | I23: OM RECEBEDORA | J23: MARCA | K23: CNPJ | L23: EMPRESA | M23: CONTATO | N23: EMAIL | O23: ATA | P23: VIGÊNCIA | Q23: OBS
A24: 9 | B24: E-14/01A/DTS | C24: MICROTRATOR COM APARADOR DE GRAMA | D24: 13 | E24: 13 | F24: =D24-E24 -> 0 | G24: 22299 | H24: ='90060_2024'!$D24*'90060_2024'!$G24 -> 289887 | I24: CINDACTA 3 | J24: Modelo: TS 142 Marca: HUSQVARNA | K24: 52.500.287/0001-12 | L24: CASA NASSER COMERCIO | M24: (19) 3656-9400 | N24: licitacoes@somassey.com.br | O24: 1195 | P24: 45834
A25: 10 | B25: E-17/01A/DTS | C25: RETROESCAVADEIRA COM PÁ CARREGADEIRA | D25: 1 | E25: 1 | F25: =D25-E25 -> 0 | G25: 386000 | H25: ='90060_2024'!$D25*'90060_2024'!$G25 -> 386000 | I25: AFA | J25: FABRICANTE/MARCA: XCMG MODELO: XC870BR-I PROCEDÊNCIA: NACIONAL | K25: 14.707.364/0001-10 | L25: XCMG BRASIL INDUSTRIA LTDA | M25: (35) 2102-0500 – ramal 10617 | N25: : agnaldo.mendes@zocarrio.com.br licitacao@xcmgbrasil.com.br T | O25: 1194 | P25: 45834 | Q25: EMPENHADO
A26: 10 | B26: E-17/01A/DTS | C26: RETROESCAVADEIRA COM PÁ CARREGADEIRA | D26: 1 | E26: 1 | F26: =D26-E26 -> 0 | G26: 386000 | H26: ='90060_2024'!$D26*'90060_2024'!$G26 -> 386000 | I26: BACG | J26: FABRICANTE/MARCA: XCMG MODELO: XC870BR-I PROCEDÊNCIA: NACIONAL | K26: 14.707.364/0001-10 | L26: XCMG BRASIL INDUSTRIA LTDA | M26: (35) 2102-0500 – ramal 10617 | N26: : agnaldo.mendes@zocarrio.com.br licitacao@xcmgbrasil.com.br T | O26: 1194 | P26: 45834 | Q26: reservado conforme Ofício nº 4579/SPOG-20/9378
A27: 10 | B27: E-17/01A/DTS | C27: RETROESCAVADEIRA COM PÁ CARREGADEIRA | D27: 1 | E27: 1 | F27: =D27-E27 -> 0 | G27: 386000 | H27: ='90060_2024'!$D27*'90060_2024'!$G27 -> 386000 | I27: BAFL | J27: FABRICANTE/MARCA: XCMG MODELO: XC870BR-I PROCEDÊNCIA: NACIONAL | K27: 14.707.364/0001-10 | L27: XCMG BRASIL INDUSTRIA LTDA | M27: (35) 2102-0500 – ramal 10617 | N27: : agnaldo.mendes@zocarrio.com.br licitacao@xcmgbrasil.com.br T | O27: 1194 | P27: 45834 | Q27: reservado conforme Ofício nº 4579/SPOG-20/9379
A28: 10 | B28: E-17/01A/DTS | C28: RETROESCAVADEIRA COM PÁ CARREGADEIRA | D28: 1 | E28: 1 | F28: =D28-E28 -> 0 | G28: 386000 | H28: ='90060_2024'!$D28*'90060_2024'!$G28 -> 386000 | I28: CPBV | J28: FABRICANTE/MARCA: XCMG MODELO: XC870BR-I PROCEDÊNCIA: NACIONAL | K28: 14.707.364/0001-10 | L28: XCMG BRASIL INDUSTRIA LTDA | M28: (35) 2102-0500 – ramal 10617 | N28: : agnaldo.mendes@zocarrio.com.br licitacao@xcmgbrasil.com.br T | O28: 1194 | P28: 45834 | Q28: reservado conforme Ofício nº 4579/SPOG-20/9380
A29: 10 | B29: E-17/01A/DTS | C29: RETROESCAVADEIRA COM PÁ CARREGADEIRA | D29: 1 | E29: 1 | F29: =D29-E29 -> 0 | G29: 386000 | H29: ='90060_2024'!$D29*'90060_2024'!$G29 -> 386000 | I29: BANT | J29: FABRICANTE/MARCA: XCMG MODELO: XC870BR-I PROCEDÊNCIA: NACIONAL | K29: 14.707.364/0001-10 | L29: XCMG BRASIL INDUSTRIA LTDA | M29: (35) 2102-0500 – ramal 10617 | N29: : agnaldo.mendes@zocarrio.com.br licitacao@xcmgbrasil.com.br T | O29: 1194 | P29: 45834
A30: 11 | B30: E-26/01A/DTS | C30: FURGÃO FRIGORÍFICO | D30: 1 | E30: 1 | F30: =D30-E30 -> 0 | G30: 275000 | H30: ='90060_2024'!$D30*'90060_2024'!$G30 -> 275000 | I30: GAP-AF | J30: RENAULT MASTER L2H2 | K30: 03.093.776/0018-30 | L30: MANUPA | M30: (11) 2478-2818 | N30: vg@manupa.com.br manupa@manupa.com.br | O30: 1190/2024 | P30: 45834
A31: 11 | B31: E-26/01A/DTS | C31: FURGÃO FRIGORÍFICO | D31: 1 | E31: 1 | F31: =D31-E31 -> 0 | G31: 275000 | H31: ='90060_2024'!$D31*'90060_2024'!$G31 -> 275000 | I31: BANT | J31: RENAULT MASTER L2H2 | K31: 03.093.776/0018-30 | L31: MANUPA | M31: (11) 2478-2818 | N31: vg@manupa.com.br manupa@manupa.com.br | O31: 1190/2024 | P31: 45834
A32: 12 | B32: P-1/02A/DTS | C32: VEÍCULO ESPECIAL | D32: 1 | E32: 0 | F32: =D32-E32 -> 1 | G32: FRACASSADO | H32: FRACASSADO | I32: CINDACTA 4 | J32: x | K32: x | L32: x | M32: x | N32: x | O32: x | P32: x | Q32: x
